2022-05-31 15:37:52,066 ERROR: Exception on /reset_password_request [POST] [in /Users/vladimirbankovic/Desktop/my_blog/venv/lib/python3.9/site-packages/flask/app.py:1457]
Traceback (most recent call last):
  File "/Users/vladimirbankovic/Desktop/my_blog/venv/lib/python3.9/site-packages/flask/app.py", line 2073, in wsgi_app
    response = self.full_dispatch_request()
  File "/Users/vladimirbankovic/Desktop/my_blog/venv/lib/python3.9/site-packages/flask/app.py", line 1518, in full_dispatch_request
    rv = self.handle_user_exception(e)
  File "/Users/vladimirbankovic/Desktop/my_blog/venv/lib/python3.9/site-packages/flask/app.py", line 1516, in full_dispatch_request
    rv = self.dispatch_request()
  File "/Users/vladimirbankovic/Desktop/my_blog/venv/lib/python3.9/site-packages/flask/app.py", line 1502, in dispatch_request
    return self.ensure_sync(self.view_functions[rule.endpoint])(**req.view_args)
  File "/Users/vladimirbankovic/Desktop/my_blog/app/routes.py", line 175, in reset_password_request
    send_password_reset_email(user)
  File "/Users/vladimirbankovic/Desktop/my_blog/app/email.py", line 19, in send_password_reset_email
    send_email('[My Blog] Reset Your Password',
TypeError: send_email() got multiple values for argument 'sender'
2022-05-31 15:39:18,487 ERROR: Exception on /reset_password_request [POST] [in /Users/vladimirbankovic/Desktop/my_blog/venv/lib/python3.9/site-packages/flask/app.py:1457]
Traceback (most recent call last):
  File "/Users/vladimirbankovic/Desktop/my_blog/venv/lib/python3.9/site-packages/flask/app.py", line 2073, in wsgi_app
    response = self.full_dispatch_request()
  File "/Users/vladimirbankovic/Desktop/my_blog/venv/lib/python3.9/site-packages/flask/app.py", line 1518, in full_dispatch_request
    rv = self.handle_user_exception(e)
  File "/Users/vladimirbankovic/Desktop/my_blog/venv/lib/python3.9/site-packages/flask/app.py", line 1516, in full_dispatch_request
    rv = self.dispatch_request()
  File "/Users/vladimirbankovic/Desktop/my_blog/venv/lib/python3.9/site-packages/flask/app.py", line 1502, in dispatch_request
    return self.ensure_sync(self.view_functions[rule.endpoint])(**req.view_args)
  File "/Users/vladimirbankovic/Desktop/my_blog/app/routes.py", line 175, in reset_password_request
    send_password_reset_email(user)
  File "/Users/vladimirbankovic/Desktop/my_blog/app/email.py", line 19, in send_password_reset_email
    send_email('[My Blog] Reset Your Password',
TypeError: send_email() got multiple values for argument 'sender'
2022-05-31 15:43:29,949 INFO: My Blog startup [in /Users/vladimirbankovic/Desktop/my_blog/app/__init__.py:45]
2022-05-31 15:43:53,976 ERROR: Exception on /reset_password_request [POST] [in /Users/vladimirbankovic/Desktop/my_blog/venv/lib/python3.9/site-packages/flask/app.py:1457]
Traceback (most recent call last):
  File "/Users/vladimirbankovic/Desktop/my_blog/venv/lib/python3.9/site-packages/flask/app.py", line 2073, in wsgi_app
    response = self.full_dispatch_request()
  File "/Users/vladimirbankovic/Desktop/my_blog/venv/lib/python3.9/site-packages/flask/app.py", line 1518, in full_dispatch_request
    rv = self.handle_user_exception(e)
  File "/Users/vladimirbankovic/Desktop/my_blog/venv/lib/python3.9/site-packages/flask/app.py", line 1516, in full_dispatch_request
    rv = self.dispatch_request()
  File "/Users/vladimirbankovic/Desktop/my_blog/venv/lib/python3.9/site-packages/flask/app.py", line 1502, in dispatch_request
    return self.ensure_sync(self.view_functions[rule.endpoint])(**req.view_args)
  File "/Users/vladimirbankovic/Desktop/my_blog/app/routes.py", line 175, in reset_password_request
    send_password_reset_email(user)
  File "/Users/vladimirbankovic/Desktop/my_blog/app/email.py", line 19, in send_password_reset_email
    send_email('[My Blog] Reset Your Password',
TypeError: send_email() got multiple values for argument 'sender'
2022-05-31 15:46:19,860 ERROR: Exception on /reset_password_request [POST] [in /Users/vladimirbankovic/Desktop/my_blog/venv/lib/python3.9/site-packages/flask/app.py:1457]
Traceback (most recent call last):
  File "/Users/vladimirbankovic/Desktop/my_blog/venv/lib/python3.9/site-packages/flask/app.py", line 2073, in wsgi_app
    response = self.full_dispatch_request()
  File "/Users/vladimirbankovic/Desktop/my_blog/venv/lib/python3.9/site-packages/flask/app.py", line 1518, in full_dispatch_request
    rv = self.handle_user_exception(e)
  File "/Users/vladimirbankovic/Desktop/my_blog/venv/lib/python3.9/site-packages/flask/app.py", line 1516, in full_dispatch_request
    rv = self.dispatch_request()
  File "/Users/vladimirbankovic/Desktop/my_blog/venv/lib/python3.9/site-packages/flask/app.py", line 1502, in dispatch_request
    return self.ensure_sync(self.view_functions[rule.endpoint])(**req.view_args)
  File "/Users/vladimirbankovic/Desktop/my_blog/app/routes.py", line 175, in reset_password_request
    send_password_reset_email(user)
  File "/Users/vladimirbankovic/Desktop/my_blog/app/email.py", line 19, in send_password_reset_email
    send_email('[My Blog] Reset Your Password',
TypeError: send_email() got multiple values for argument 'sender'
2022-05-31 15:50:03,760 INFO: My Blog startup [in /Users/vladimirbankovic/Desktop/my_blog/app/__init__.py:45]
2022-05-31 15:50:21,000 ERROR: Exception on /reset_password_request [POST] [in /Users/vladimirbankovic/Desktop/my_blog/venv/lib/python3.9/site-packages/flask/app.py:1457]
Traceback (most recent call last):
  File "/Users/vladimirbankovic/Desktop/my_blog/venv/lib/python3.9/site-packages/flask/app.py", line 2073, in wsgi_app
    response = self.full_dispatch_request()
  File "/Users/vladimirbankovic/Desktop/my_blog/venv/lib/python3.9/site-packages/flask/app.py", line 1518, in full_dispatch_request
    rv = self.handle_user_exception(e)
  File "/Users/vladimirbankovic/Desktop/my_blog/venv/lib/python3.9/site-packages/flask/app.py", line 1516, in full_dispatch_request
    rv = self.dispatch_request()
  File "/Users/vladimirbankovic/Desktop/my_blog/venv/lib/python3.9/site-packages/flask/app.py", line 1502, in dispatch_request
    return self.ensure_sync(self.view_functions[rule.endpoint])(**req.view_args)
  File "/Users/vladimirbankovic/Desktop/my_blog/app/routes.py", line 175, in reset_password_request
    send_password_reset_email(user)
  File "/Users/vladimirbankovic/Desktop/my_blog/app/email.py", line 19, in send_password_reset_email
    send_email('[My Blog] Reset Your Password',
TypeError: send_email() got multiple values for argument 'sender'
2022-05-31 16:44:20,365 INFO: My Blog startup [in /Users/vladimirbankovic/Desktop/my_blog/app/__init__.py:45]
2022-05-31 16:44:28,316 ERROR: Exception on /reset_password_request [POST] [in /Users/vladimirbankovic/Desktop/my_blog/venv/lib/python3.9/site-packages/flask/app.py:1457]
Traceback (most recent call last):
  File "/Users/vladimirbankovic/Desktop/my_blog/venv/lib/python3.9/site-packages/flask/app.py", line 2073, in wsgi_app
    response = self.full_dispatch_request()
  File "/Users/vladimirbankovic/Desktop/my_blog/venv/lib/python3.9/site-packages/flask/app.py", line 1518, in full_dispatch_request
    rv = self.handle_user_exception(e)
  File "/Users/vladimirbankovic/Desktop/my_blog/venv/lib/python3.9/site-packages/flask/app.py", line 1516, in full_dispatch_request
    rv = self.dispatch_request()
  File "/Users/vladimirbankovic/Desktop/my_blog/venv/lib/python3.9/site-packages/flask/app.py", line 1502, in dispatch_request
    return self.ensure_sync(self.view_functions[rule.endpoint])(**req.view_args)
  File "/Users/vladimirbankovic/Desktop/my_blog/app/routes.py", line 175, in reset_password_request
    send_password_reset_email(user)
  File "/Users/vladimirbankovic/Desktop/my_blog/app/email.py", line 19, in send_password_reset_email
    send_email('[My Blog] Reset Your Password',
TypeError: send_email() got multiple values for argument 'sender'
2022-06-01 14:25:36,779 INFO: My Blog startup [in /Users/vladimirbankovic/Desktop/my_blog/app/__init__.py:45]
2022-06-01 14:43:41,411 ERROR: Exception on /reset_password_request [POST] [in /Users/vladimirbankovic/Desktop/my_blog/venv/lib/python3.9/site-packages/flask/app.py:1457]
Traceback (most recent call last):
  File "/Users/vladimirbankovic/Desktop/my_blog/venv/lib/python3.9/site-packages/flask/app.py", line 2073, in wsgi_app
    response = self.full_dispatch_request()
  File "/Users/vladimirbankovic/Desktop/my_blog/venv/lib/python3.9/site-packages/flask/app.py", line 1518, in full_dispatch_request
    rv = self.handle_user_exception(e)
  File "/Users/vladimirbankovic/Desktop/my_blog/venv/lib/python3.9/site-packages/flask/app.py", line 1516, in full_dispatch_request
    rv = self.dispatch_request()
  File "/Users/vladimirbankovic/Desktop/my_blog/venv/lib/python3.9/site-packages/flask/app.py", line 1502, in dispatch_request
    return self.ensure_sync(self.view_functions[rule.endpoint])(**req.view_args)
  File "/Users/vladimirbankovic/Desktop/my_blog/app/routes.py", line 175, in reset_password_request
    send_password_reset_email(user)
  File "/Users/vladimirbankovic/Desktop/my_blog/app/email.py", line 19, in send_password_reset_email
    send_email('[My Blog] Reset Your Password',
TypeError: send_email() got multiple values for argument 'sender'
2022-06-01 14:44:07,177 INFO: My Blog startup [in /Users/vladimirbankovic/Desktop/my_blog/app/__init__.py:45]
